ERROR 2023-11-28 22:47:17,592 log 27488 29504 Internal Server Error: /apiv2/send_test_mailing/
ERROR 2023-11-28 22:47:17,593 basehttp 27488 29504 "POST /apiv2/send_test_mailing/ HTTP/1.1" 500 41
ERROR 2023-11-28 22:48:04,634 log 29756 26896 Internal Server Error: /apiv2/send_test_mailing/
ERROR 2023-11-28 22:48:04,635 basehttp 29756 26896 "POST /apiv2/send_test_mailing/ HTTP/1.1" 500 41
ERROR 2023-11-28 22:52:43,393 log 27712 29180 Internal Server Error: /apiv2/send_test_mailing/
ERROR 2023-11-28 22:52:43,394 basehttp 27712 29180 "POST /apiv2/send_test_mailing/ HTTP/1.1" 500 263
ERROR 2023-11-28 22:53:29,936 log 15776 3396 Internal Server Error: /apiv2/send_test_mailing/
ERROR 2023-11-28 22:53:29,938 basehttp 15776 3396 "POST /apiv2/send_test_mailing/ HTTP/1.1" 500 373
ERROR 2023-11-28 22:53:52,165 log 15776 3396 Internal Server Error: /apiv2/send_test_mailing/
ERROR 2023-11-28 22:53:52,166 basehttp 15776 3396 "POST /apiv2/send_test_mailing/ HTTP/1.1" 500 373
ERROR 2023-11-28 23:23:55,125 log 29820 17932 Internal Server Error: /apiv2/send_test_mailing/
ERROR 2023-11-28 23:23:55,126 basehttp 29820 17932 "POST /apiv2/send_test_mailing/ HTTP/1.1" 500 295
ERROR 2023-11-28 23:27:13,557 log 28988 14164 Internal Server Error: /apiv2/send_test_mailing/
ERROR 2023-11-28 23:27:13,559 basehttp 28988 14164 "POST /apiv2/send_test_mailing/ HTTP/1.1" 500 295
ERROR 2023-11-29 23:51:00,294 log 10696 7872 Internal Server Error: /apiv2/send_test_mailing/
ERROR 2023-11-29 23:51:00,295 basehttp 10696 7872 "POST /apiv2/send_test_mailing/ HTTP/1.1" 500 596
ERROR 2023-11-29 23:54:03,573 log 10696 21396 Internal Server Error: /apiv2/send_test_mailing/
ERROR 2023-11-29 23:54:03,574 basehttp 10696 21396 "POST /apiv2/send_test_mailing/ HTTP/1.1" 500 293
ERROR 2023-11-29 23:55:16,360 log 10696 21396 Internal Server Error: /apiv2/send_test_mailing/
ERROR 2023-11-29 23:55:16,362 basehttp 10696 21396 "POST /apiv2/send_test_mailing/ HTTP/1.1" 500 293
ERROR 2023-11-29 23:57:08,506 log 23816 8068 Internal Server Error: /apiv2/send_test_mailing/
ERROR 2023-11-29 23:57:08,507 basehttp 23816 8068 "POST /apiv2/send_test_mailing/ HTTP/1.1" 500 293
ERROR 2023-11-30 00:47:26,641 log 24792 2484 Internal Server Error: /apiv2/send_test_mailing/
ERROR 2023-11-30 00:47:26,642 basehttp 24792 2484 "POST /apiv2/send_test_mailing/ HTTP/1.1" 500 423
ERROR 2023-11-30 00:47:43,045 log 24792 2484 Internal Server Error: /apiv2/send_test_mailing/
ERROR 2023-11-30 00:47:43,046 basehttp 24792 2484 "POST /apiv2/send_test_mailing/ HTTP/1.1" 500 423
ERROR 2023-12-03 21:35:33,730 log 2580 23344 Internal Server Error: /apiv2/send_test_mailing/
ERROR 2023-12-03 21:35:33,731 basehttp 2580 23344 "POST /apiv2/send_test_mailing/ HTTP/1.1" 500 595
ERROR 2023-12-04 00:03:36,714 log 9872 19068 Internal Server Error: /apiv2/send_test_mailing/
ERROR 2023-12-04 00:03:36,726 basehttp 9872 19068 "POST /apiv2/send_test_mailing/ HTTP/1.1" 500 254
ERROR 2023-12-04 00:04:27,220 log 21452 20668 Internal Server Error: /apiv2/send_test_mailing/
ERROR 2023-12-04 00:04:27,221 basehttp 21452 20668 "POST /apiv2/send_test_mailing/ HTTP/1.1" 500 254
ERROR 2023-12-04 00:19:39,127 log 21452 26500 Internal Server Error: /apiv2/send_test_mailing/
ERROR 2023-12-04 00:19:39,128 basehttp 21452 26500 "POST /apiv2/send_test_mailing/ HTTP/1.1" 500 254
ERROR 2023-12-05 15:05:47,088 log 23016 30976 Internal Server Error: /apiv2/send_test_mailing/
ERROR 2023-12-05 15:05:47,088 basehttp 23016 30976 "POST /apiv2/send_test_mailing/ HTTP/1.1" 500 254
ERROR 2023-12-05 15:11:48,963 log 24892 11504 Internal Server Error: /apiv2/send_test_mailing/
ERROR 2023-12-05 15:11:48,964 basehttp 24892 11504 "POST /apiv2/send_test_mailing/ HTTP/1.1" 500 286
ERROR 2023-12-05 17:50:06,253 log 20384 25132 Internal Server Error: /apiv2/send_test_mailing/
ERROR 2023-12-05 17:50:06,254 basehttp 20384 25132 "POST /apiv2/send_test_mailing/ HTTP/1.1" 500 286
ERROR 2023-12-06 11:37:41,420 log 27404 24816 Internal Server Error: /client/1/
Traceback (most recent call last):
  File "C:\Users\Adena\AppData\Local\Packages\PythonSoftwareFoundation.Python.3.10_qbz5n2kfra8p0\LocalCache\local-packages\Python310\site-packages\django\db\backends\utils.py", line 89, in _execute
    return self.cursor.execute(sql, params)
psycopg2.errors.UndefinedColumn: ОШИБКА:  столбец users_boardmaps.test_automatic_email не существует
LINE 1: ...boardmaps"."email", "users_boardmaps"."position", "users_boa...
                                                             ^


The above exception was the direct cause of the following exception:

Traceback (most recent call last):
  File "C:\Users\Adena\AppData\Local\Packages\PythonSoftwareFoundation.Python.3.10_qbz5n2kfra8p0\LocalCache\local-packages\Python310\site-packages\django\core\handlers\exception.py", line 55, in inner
    response = get_response(request)
  File "C:\Users\Adena\AppData\Local\Packages\PythonSoftwareFoundation.Python.3.10_qbz5n2kfra8p0\LocalCache\local-packages\Python310\site-packages\django\core\handlers\base.py", line 197, in _get_response
    response = wrapped_callback(request, *callback_args, **callback_kwargs)
  File "D:\Script\BoardMaps\TFS\Crag\main\views.py", line 386, in client
    return render(request, 'main/client/client.html', {
  File "C:\Users\Adena\AppData\Local\Packages\PythonSoftwareFoundation.Python.3.10_qbz5n2kfra8p0\LocalCache\local-packages\Python310\site-packages\django\shortcuts.py", line 24, in render
    content = loader.render_to_string(template_name, context, request, using=using)
  File "C:\Users\Adena\AppData\Local\Packages\PythonSoftwareFoundation.Python.3.10_qbz5n2kfra8p0\LocalCache\local-packages\Python310\site-packages\django\template\loader.py", line 62, in render_to_string
    return template.render(context, request)
  File "C:\Users\Adena\AppData\Local\Packages\PythonSoftwareFoundation.Python.3.10_qbz5n2kfra8p0\LocalCache\local-packages\Python310\site-packages\django\template\backends\django.py", line 61, in render
    return self.template.render(context)
  File "C:\Users\Adena\AppData\Local\Packages\PythonSoftwareFoundation.Python.3.10_qbz5n2kfra8p0\LocalCache\local-packages\Python310\site-packages\django\template\base.py", line 175, in render
    return self._render(context)
  File "C:\Users\Adena\AppData\Local\Packages\PythonSoftwareFoundation.Python.3.10_qbz5n2kfra8p0\LocalCache\local-packages\Python310\site-packages\django\template\base.py", line 167, in _render
    return self.nodelist.render(context)
  File "C:\Users\Adena\AppData\Local\Packages\PythonSoftwareFoundation.Python.3.10_qbz5n2kfra8p0\LocalCache\local-packages\Python310\site-packages\django\template\base.py", line 1005, in render
    return SafeString("".join([node.render_annotated(context) for node in self]))
  File "C:\Users\Adena\AppData\Local\Packages\PythonSoftwareFoundation.Python.3.10_qbz5n2kfra8p0\LocalCache\local-packages\Python310\site-packages\django\template\base.py", line 1005, in <listcomp>
    return SafeString("".join([node.render_annotated(context) for node in self]))
  File "C:\Users\Adena\AppData\Local\Packages\PythonSoftwareFoundation.Python.3.10_qbz5n2kfra8p0\LocalCache\local-packages\Python310\site-packages\django\template\base.py", line 966, in render_annotated
    return self.render(context)
  File "C:\Users\Adena\AppData\Local\Packages\PythonSoftwareFoundation.Python.3.10_qbz5n2kfra8p0\LocalCache\local-packages\Python310\site-packages\django\template\loader_tags.py", line 157, in render
    return compiled_parent._render(context)
  File "C:\Users\Adena\AppData\Local\Packages\PythonSoftwareFoundation.Python.3.10_qbz5n2kfra8p0\LocalCache\local-packages\Python310\site-packages\django\template\base.py", line 167, in _render
    return self.nodelist.render(context)
  File "C:\Users\Adena\AppData\Local\Packages\PythonSoftwareFoundation.Python.3.10_qbz5n2kfra8p0\LocalCache\local-packages\Python310\site-packages\django\template\base.py", line 1005, in render
    return SafeString("".join([node.render_annotated(context) for node in self]))
  File "C:\Users\Adena\AppData\Local\Packages\PythonSoftwareFoundation.Python.3.10_qbz5n2kfra8p0\LocalCache\local-packages\Python310\site-packages\django\template\base.py", line 1005, in <listcomp>
    return SafeString("".join([node.render_annotated(context) for node in self]))
  File "C:\Users\Adena\AppData\Local\Packages\PythonSoftwareFoundation.Python.3.10_qbz5n2kfra8p0\LocalCache\local-packages\Python310\site-packages\django\template\base.py", line 966, in render_annotated
    return self.render(context)
  File "C:\Users\Adena\AppData\Local\Packages\PythonSoftwareFoundation.Python.3.10_qbz5n2kfra8p0\LocalCache\local-packages\Python310\site-packages\django\template\loader_tags.py", line 63, in render
    result = block.nodelist.render(context)
  File "C:\Users\Adena\AppData\Local\Packages\PythonSoftwareFoundation.Python.3.10_qbz5n2kfra8p0\LocalCache\local-packages\Python310\site-packages\django\template\base.py", line 1005, in render
    return SafeString("".join([node.render_annotated(context) for node in self]))
  File "C:\Users\Adena\AppData\Local\Packages\PythonSoftwareFoundation.Python.3.10_qbz5n2kfra8p0\LocalCache\local-packages\Python310\site-packages\django\template\base.py", line 1005, in <listcomp>
    return SafeString("".join([node.render_annotated(context) for node in self]))
  File "C:\Users\Adena\AppData\Local\Packages\PythonSoftwareFoundation.Python.3.10_qbz5n2kfra8p0\LocalCache\local-packages\Python310\site-packages\django\template\base.py", line 966, in render_annotated
    return self.render(context)
  File "C:\Users\Adena\AppData\Local\Packages\PythonSoftwareFoundation.Python.3.10_qbz5n2kfra8p0\LocalCache\local-packages\Python310\site-packages\django\template\defaulttags.py", line 194, in render
    len_values = len(values)
  File "C:\Users\Adena\AppData\Local\Packages\PythonSoftwareFoundation.Python.3.10_qbz5n2kfra8p0\LocalCache\local-packages\Python310\site-packages\django\db\models\query.py", line 380, in __len__
    self._fetch_all()
  File "C:\Users\Adena\AppData\Local\Packages\PythonSoftwareFoundation.Python.3.10_qbz5n2kfra8p0\LocalCache\local-packages\Python310\site-packages\django\db\models\query.py", line 1881, in _fetch_all
    self._result_cache = list(self._iterable_class(self))
  File "C:\Users\Adena\AppData\Local\Packages\PythonSoftwareFoundation.Python.3.10_qbz5n2kfra8p0\LocalCache\local-packages\Python310\site-packages\django\db\models\query.py", line 91, in __iter__
    results = compiler.execute_sql(
  File "C:\Users\Adena\AppData\Local\Packages\PythonSoftwareFoundation.Python.3.10_qbz5n2kfra8p0\LocalCache\local-packages\Python310\site-packages\django\db\models\sql\compiler.py", line 1562, in execute_sql
    cursor.execute(sql, params)
  File "C:\Users\Adena\AppData\Local\Packages\PythonSoftwareFoundation.Python.3.10_qbz5n2kfra8p0\LocalCache\local-packages\Python310\site-packages\django\db\backends\utils.py", line 102, in execute
    return super().execute(sql, params)
  File "C:\Users\Adena\AppData\Local\Packages\PythonSoftwareFoundation.Python.3.10_qbz5n2kfra8p0\LocalCache\local-packages\Python310\site-packages\django\db\backends\utils.py", line 67, in execute
    return self._execute_with_wrappers(
  File "C:\Users\Adena\AppData\Local\Packages\PythonSoftwareFoundation.Python.3.10_qbz5n2kfra8p0\LocalCache\local-packages\Python310\site-packages\django\db\backends\utils.py", line 80, in _execute_with_wrappers
    return executor(sql, params, many, context)
  File "C:\Users\Adena\AppData\Local\Packages\PythonSoftwareFoundation.Python.3.10_qbz5n2kfra8p0\LocalCache\local-packages\Python310\site-packages\django\db\backends\utils.py", line 84, in _execute
    with self.db.wrap_database_errors:
  File "C:\Users\Adena\AppData\Local\Packages\PythonSoftwareFoundation.Python.3.10_qbz5n2kfra8p0\LocalCache\local-packages\Python310\site-packages\django\db\utils.py", line 91, in __exit__
    raise dj_exc_value.with_traceback(traceback) from exc_value
  File "C:\Users\Adena\AppData\Local\Packages\PythonSoftwareFoundation.Python.3.10_qbz5n2kfra8p0\LocalCache\local-packages\Python310\site-packages\django\db\backends\utils.py", line 89, in _execute
    return self.cursor.execute(sql, params)
django.db.utils.ProgrammingError: ОШИБКА:  столбец users_boardmaps.test_automatic_email не существует
LINE 1: ...boardmaps"."email", "users_boardmaps"."position", "users_boa...
                                                             ^

ERROR 2023-12-06 11:37:41,429 basehttp 27404 24816 "GET /client/1/ HTTP/1.1" 500 261935
ERROR 2023-12-06 11:37:50,577 log 27404 24816 Internal Server Error: /client/2/
Traceback (most recent call last):
  File "C:\Users\Adena\AppData\Local\Packages\PythonSoftwareFoundation.Python.3.10_qbz5n2kfra8p0\LocalCache\local-packages\Python310\site-packages\django\db\backends\utils.py", line 89, in _execute
    return self.cursor.execute(sql, params)
psycopg2.errors.UndefinedColumn: ОШИБКА:  столбец users_boardmaps.test_automatic_email не существует
LINE 1: ...boardmaps"."email", "users_boardmaps"."position", "users_boa...
                                                             ^


The above exception was the direct cause of the following exception:

Traceback (most recent call last):
  File "C:\Users\Adena\AppData\Local\Packages\PythonSoftwareFoundation.Python.3.10_qbz5n2kfra8p0\LocalCache\local-packages\Python310\site-packages\django\core\handlers\exception.py", line 55, in inner
    response = get_response(request)
  File "C:\Users\Adena\AppData\Local\Packages\PythonSoftwareFoundation.Python.3.10_qbz5n2kfra8p0\LocalCache\local-packages\Python310\site-packages\django\core\handlers\base.py", line 197, in _get_response
    response = wrapped_callback(request, *callback_args, **callback_kwargs)
  File "D:\Script\BoardMaps\TFS\Crag\main\views.py", line 386, in client
    return render(request, 'main/client/client.html', {
  File "C:\Users\Adena\AppData\Local\Packages\PythonSoftwareFoundation.Python.3.10_qbz5n2kfra8p0\LocalCache\local-packages\Python310\site-packages\django\shortcuts.py", line 24, in render
    content = loader.render_to_string(template_name, context, request, using=using)
  File "C:\Users\Adena\AppData\Local\Packages\PythonSoftwareFoundation.Python.3.10_qbz5n2kfra8p0\LocalCache\local-packages\Python310\site-packages\django\template\loader.py", line 62, in render_to_string
    return template.render(context, request)
  File "C:\Users\Adena\AppData\Local\Packages\PythonSoftwareFoundation.Python.3.10_qbz5n2kfra8p0\LocalCache\local-packages\Python310\site-packages\django\template\backends\django.py", line 61, in render
    return self.template.render(context)
  File "C:\Users\Adena\AppData\Local\Packages\PythonSoftwareFoundation.Python.3.10_qbz5n2kfra8p0\LocalCache\local-packages\Python310\site-packages\django\template\base.py", line 175, in render
    return self._render(context)
  File "C:\Users\Adena\AppData\Local\Packages\PythonSoftwareFoundation.Python.3.10_qbz5n2kfra8p0\LocalCache\local-packages\Python310\site-packages\django\template\base.py", line 167, in _render
    return self.nodelist.render(context)
  File "C:\Users\Adena\AppData\Local\Packages\PythonSoftwareFoundation.Python.3.10_qbz5n2kfra8p0\LocalCache\local-packages\Python310\site-packages\django\template\base.py", line 1005, in render
    return SafeString("".join([node.render_annotated(context) for node in self]))
  File "C:\Users\Adena\AppData\Local\Packages\PythonSoftwareFoundation.Python.3.10_qbz5n2kfra8p0\LocalCache\local-packages\Python310\site-packages\django\template\base.py", line 1005, in <listcomp>
    return SafeString("".join([node.render_annotated(context) for node in self]))
  File "C:\Users\Adena\AppData\Local\Packages\PythonSoftwareFoundation.Python.3.10_qbz5n2kfra8p0\LocalCache\local-packages\Python310\site-packages\django\template\base.py", line 966, in render_annotated
    return self.render(context)
  File "C:\Users\Adena\AppData\Local\Packages\PythonSoftwareFoundation.Python.3.10_qbz5n2kfra8p0\LocalCache\local-packages\Python310\site-packages\django\template\loader_tags.py", line 157, in render
    return compiled_parent._render(context)
  File "C:\Users\Adena\AppData\Local\Packages\PythonSoftwareFoundation.Python.3.10_qbz5n2kfra8p0\LocalCache\local-packages\Python310\site-packages\django\template\base.py", line 167, in _render
    return self.nodelist.render(context)
  File "C:\Users\Adena\AppData\Local\Packages\PythonSoftwareFoundation.Python.3.10_qbz5n2kfra8p0\LocalCache\local-packages\Python310\site-packages\django\template\base.py", line 1005, in render
    return SafeString("".join([node.render_annotated(context) for node in self]))
  File "C:\Users\Adena\AppData\Local\Packages\PythonSoftwareFoundation.Python.3.10_qbz5n2kfra8p0\LocalCache\local-packages\Python310\site-packages\django\template\base.py", line 1005, in <listcomp>
    return SafeString("".join([node.render_annotated(context) for node in self]))
  File "C:\Users\Adena\AppData\Local\Packages\PythonSoftwareFoundation.Python.3.10_qbz5n2kfra8p0\LocalCache\local-packages\Python310\site-packages\django\template\base.py", line 966, in render_annotated
    return self.render(context)
  File "C:\Users\Adena\AppData\Local\Packages\PythonSoftwareFoundation.Python.3.10_qbz5n2kfra8p0\LocalCache\local-packages\Python310\site-packages\django\template\loader_tags.py", line 63, in render
    result = block.nodelist.render(context)
  File "C:\Users\Adena\AppData\Local\Packages\PythonSoftwareFoundation.Python.3.10_qbz5n2kfra8p0\LocalCache\local-packages\Python310\site-packages\django\template\base.py", line 1005, in render
    return SafeString("".join([node.render_annotated(context) for node in self]))
  File "C:\Users\Adena\AppData\Local\Packages\PythonSoftwareFoundation.Python.3.10_qbz5n2kfra8p0\LocalCache\local-packages\Python310\site-packages\django\template\base.py", line 1005, in <listcomp>
    return SafeString("".join([node.render_annotated(context) for node in self]))
  File "C:\Users\Adena\AppData\Local\Packages\PythonSoftwareFoundation.Python.3.10_qbz5n2kfra8p0\LocalCache\local-packages\Python310\site-packages\django\template\base.py", line 966, in render_annotated
    return self.render(context)
  File "C:\Users\Adena\AppData\Local\Packages\PythonSoftwareFoundation.Python.3.10_qbz5n2kfra8p0\LocalCache\local-packages\Python310\site-packages\django\template\defaulttags.py", line 194, in render
    len_values = len(values)
  File "C:\Users\Adena\AppData\Local\Packages\PythonSoftwareFoundation.Python.3.10_qbz5n2kfra8p0\LocalCache\local-packages\Python310\site-packages\django\db\models\query.py", line 380, in __len__
    self._fetch_all()
  File "C:\Users\Adena\AppData\Local\Packages\PythonSoftwareFoundation.Python.3.10_qbz5n2kfra8p0\LocalCache\local-packages\Python310\site-packages\django\db\models\query.py", line 1881, in _fetch_all
    self._result_cache = list(self._iterable_class(self))
  File "C:\Users\Adena\AppData\Local\Packages\PythonSoftwareFoundation.Python.3.10_qbz5n2kfra8p0\LocalCache\local-packages\Python310\site-packages\django\db\models\query.py", line 91, in __iter__
    results = compiler.execute_sql(
  File "C:\Users\Adena\AppData\Local\Packages\PythonSoftwareFoundation.Python.3.10_qbz5n2kfra8p0\LocalCache\local-packages\Python310\site-packages\django\db\models\sql\compiler.py", line 1562, in execute_sql
    cursor.execute(sql, params)
  File "C:\Users\Adena\AppData\Local\Packages\PythonSoftwareFoundation.Python.3.10_qbz5n2kfra8p0\LocalCache\local-packages\Python310\site-packages\django\db\backends\utils.py", line 102, in execute
    return super().execute(sql, params)
  File "C:\Users\Adena\AppData\Local\Packages\PythonSoftwareFoundation.Python.3.10_qbz5n2kfra8p0\LocalCache\local-packages\Python310\site-packages\django\db\backends\utils.py", line 67, in execute
    return self._execute_with_wrappers(
  File "C:\Users\Adena\AppData\Local\Packages\PythonSoftwareFoundation.Python.3.10_qbz5n2kfra8p0\LocalCache\local-packages\Python310\site-packages\django\db\backends\utils.py", line 80, in _execute_with_wrappers
    return executor(sql, params, many, context)
  File "C:\Users\Adena\AppData\Local\Packages\PythonSoftwareFoundation.Python.3.10_qbz5n2kfra8p0\LocalCache\local-packages\Python310\site-packages\django\db\backends\utils.py", line 84, in _execute
    with self.db.wrap_database_errors:
  File "C:\Users\Adena\AppData\Local\Packages\PythonSoftwareFoundation.Python.3.10_qbz5n2kfra8p0\LocalCache\local-packages\Python310\site-packages\django\db\utils.py", line 91, in __exit__
    raise dj_exc_value.with_traceback(traceback) from exc_value
  File "C:\Users\Adena\AppData\Local\Packages\PythonSoftwareFoundation.Python.3.10_qbz5n2kfra8p0\LocalCache\local-packages\Python310\site-packages\django\db\backends\utils.py", line 89, in _execute
    return self.cursor.execute(sql, params)
django.db.utils.ProgrammingError: ОШИБКА:  столбец users_boardmaps.test_automatic_email не существует
LINE 1: ...boardmaps"."email", "users_boardmaps"."position", "users_boa...
                                                             ^

ERROR 2023-12-06 11:37:50,585 basehttp 27404 24816 "GET /client/2/ HTTP/1.1" 500 262176
ERROR 2023-12-06 11:38:08,749 log 27404 25708 Internal Server Error: /admin/main/usersboardmaps/
Traceback (most recent call last):
  File "C:\Users\Adena\AppData\Local\Packages\PythonSoftwareFoundation.Python.3.10_qbz5n2kfra8p0\LocalCache\local-packages\Python310\site-packages\django\db\backends\utils.py", line 89, in _execute
    return self.cursor.execute(sql, params)
psycopg2.errors.UndefinedColumn: ОШИБКА:  столбец users_boardmaps.test_automatic_email не существует
LINE 1: ...boardmaps"."email", "users_boardmaps"."position", "users_boa...
                                                             ^


The above exception was the direct cause of the following exception:

Traceback (most recent call last):
  File "C:\Users\Adena\AppData\Local\Packages\PythonSoftwareFoundation.Python.3.10_qbz5n2kfra8p0\LocalCache\local-packages\Python310\site-packages\django\core\handlers\exception.py", line 55, in inner
    response = get_response(request)
  File "C:\Users\Adena\AppData\Local\Packages\PythonSoftwareFoundation.Python.3.10_qbz5n2kfra8p0\LocalCache\local-packages\Python310\site-packages\django\core\handlers\base.py", line 197, in _get_response
    response = wrapped_callback(request, *callback_args, **callback_kwargs)
  File "C:\Users\Adena\AppData\Local\Packages\PythonSoftwareFoundation.Python.3.10_qbz5n2kfra8p0\LocalCache\local-packages\Python310\site-packages\django\contrib\admin\options.py", line 688, in wrapper
    return self.admin_site.admin_view(view)(*args, **kwargs)
  File "C:\Users\Adena\AppData\Local\Packages\PythonSoftwareFoundation.Python.3.10_qbz5n2kfra8p0\LocalCache\local-packages\Python310\site-packages\django\utils\decorators.py", line 134, in _wrapper_view
    response = view_func(request, *args, **kwargs)
  File "C:\Users\Adena\AppData\Local\Packages\PythonSoftwareFoundation.Python.3.10_qbz5n2kfra8p0\LocalCache\local-packages\Python310\site-packages\django\views\decorators\cache.py", line 62, in _wrapper_view_func
    response = view_func(request, *args, **kwargs)
  File "C:\Users\Adena\AppData\Local\Packages\PythonSoftwareFoundation.Python.3.10_qbz5n2kfra8p0\LocalCache\local-packages\Python310\site-packages\django\contrib\admin\sites.py", line 242, in inner
    return view(request, *args, **kwargs)
  File "C:\Users\Adena\AppData\Local\Packages\PythonSoftwareFoundation.Python.3.10_qbz5n2kfra8p0\LocalCache\local-packages\Python310\site-packages\django\utils\decorators.py", line 46, in _wrapper
    return bound_method(*args, **kwargs)
  File "C:\Users\Adena\AppData\Local\Packages\PythonSoftwareFoundation.Python.3.10_qbz5n2kfra8p0\LocalCache\local-packages\Python310\site-packages\django\utils\decorators.py", line 134, in _wrapper_view
    response = view_func(request, *args, **kwargs)
  File "C:\Users\Adena\AppData\Local\Packages\PythonSoftwareFoundation.Python.3.10_qbz5n2kfra8p0\LocalCache\local-packages\Python310\site-packages\django\contrib\admin\options.py", line 2065, in changelist_view
    "selection_note": _("0 of %(cnt)s selected") % {"cnt": len(cl.result_list)},
  File "C:\Users\Adena\AppData\Local\Packages\PythonSoftwareFoundation.Python.3.10_qbz5n2kfra8p0\LocalCache\local-packages\Python310\site-packages\django\db\models\query.py", line 380, in __len__
    self._fetch_all()
  File "C:\Users\Adena\AppData\Local\Packages\PythonSoftwareFoundation.Python.3.10_qbz5n2kfra8p0\LocalCache\local-packages\Python310\site-packages\django\db\models\query.py", line 1881, in _fetch_all
    self._result_cache = list(self._iterable_class(self))
  File "C:\Users\Adena\AppData\Local\Packages\PythonSoftwareFoundation.Python.3.10_qbz5n2kfra8p0\LocalCache\local-packages\Python310\site-packages\django\db\models\query.py", line 91, in __iter__
    results = compiler.execute_sql(
  File "C:\Users\Adena\AppData\Local\Packages\PythonSoftwareFoundation.Python.3.10_qbz5n2kfra8p0\LocalCache\local-packages\Python310\site-packages\django\db\models\sql\compiler.py", line 1562, in execute_sql
    cursor.execute(sql, params)
  File "C:\Users\Adena\AppData\Local\Packages\PythonSoftwareFoundation.Python.3.10_qbz5n2kfra8p0\LocalCache\local-packages\Python310\site-packages\django\db\backends\utils.py", line 102, in execute
    return super().execute(sql, params)
  File "C:\Users\Adena\AppData\Local\Packages\PythonSoftwareFoundation.Python.3.10_qbz5n2kfra8p0\LocalCache\local-packages\Python310\site-packages\django\db\backends\utils.py", line 67, in execute
    return self._execute_with_wrappers(
  File "C:\Users\Adena\AppData\Local\Packages\PythonSoftwareFoundation.Python.3.10_qbz5n2kfra8p0\LocalCache\local-packages\Python310\site-packages\django\db\backends\utils.py", line 80, in _execute_with_wrappers
    return executor(sql, params, many, context)
  File "C:\Users\Adena\AppData\Local\Packages\PythonSoftwareFoundation.Python.3.10_qbz5n2kfra8p0\LocalCache\local-packages\Python310\site-packages\django\db\backends\utils.py", line 84, in _execute
    with self.db.wrap_database_errors:
  File "C:\Users\Adena\AppData\Local\Packages\PythonSoftwareFoundation.Python.3.10_qbz5n2kfra8p0\LocalCache\local-packages\Python310\site-packages\django\db\utils.py", line 91, in __exit__
    raise dj_exc_value.with_traceback(traceback) from exc_value
  File "C:\Users\Adena\AppData\Local\Packages\PythonSoftwareFoundation.Python.3.10_qbz5n2kfra8p0\LocalCache\local-packages\Python310\site-packages\django\db\backends\utils.py", line 89, in _execute
    return self.cursor.execute(sql, params)
django.db.utils.ProgrammingError: ОШИБКА:  столбец users_boardmaps.test_automatic_email не существует
LINE 1: ...boardmaps"."email", "users_boardmaps"."position", "users_boa...
                                                             ^

ERROR 2023-12-06 11:38:08,756 basehttp 27404 25708 "GET /admin/main/usersboardmaps/ HTTP/1.1" 500 176324
ERROR 2023-12-06 14:38:53,841 log 27228 1068 Internal Server Error: /apiv2/connect_info/delete/23/
Traceback (most recent call last):
  File "C:\Users\Adena\AppData\Local\Packages\PythonSoftwareFoundation.Python.3.10_qbz5n2kfra8p0\LocalCache\local-packages\Python310\site-packages\django\core\handlers\exception.py", line 55, in inner
    response = get_response(request)
  File "C:\Users\Adena\AppData\Local\Packages\PythonSoftwareFoundation.Python.3.10_qbz5n2kfra8p0\LocalCache\local-packages\Python310\site-packages\django\core\handlers\base.py", line 197, in _get_response
    response = wrapped_callback(request, *callback_args, **callback_kwargs)
  File "C:\Users\Adena\AppData\Local\Packages\PythonSoftwareFoundation.Python.3.10_qbz5n2kfra8p0\LocalCache\local-packages\Python310\site-packages\django\views\decorators\csrf.py", line 56, in wrapper_view
    return view_func(*args, **kwargs)
  File "C:\Users\Adena\AppData\Local\Packages\PythonSoftwareFoundation.Python.3.10_qbz5n2kfra8p0\LocalCache\local-packages\Python310\site-packages\django\views\decorators\http.py", line 43, in inner
    return func(request, *args, **kwargs)
TypeError: delete_connect_info() got an unexpected keyword argument 'connect_info_id'
ERROR 2023-12-06 14:38:53,844 basehttp 27228 1068 "DELETE /apiv2/connect_info/delete/23/ HTTP/1.1" 500 93324
ERROR 2023-12-06 20:47:53,576 log 28732 11976 Internal Server Error: /search_results/
Traceback (most recent call last):
  File "C:\Users\Adena\AppData\Local\Packages\PythonSoftwareFoundation.Python.3.10_qbz5n2kfra8p0\LocalCache\local-packages\Python310\site-packages\django\core\handlers\exception.py", line 55, in inner
    response = get_response(request)
  File "C:\Users\Adena\AppData\Local\Packages\PythonSoftwareFoundation.Python.3.10_qbz5n2kfra8p0\LocalCache\local-packages\Python310\site-packages\django\core\handlers\base.py", line 197, in _get_response
    response = wrapped_callback(request, *callback_args, **callback_kwargs)
  File "D:\Script\BoardMaps\TFS\Crag\main\views.py", line 216, in search_results
    for result in results:
UnboundLocalError: local variable 'results' referenced before assignment
ERROR 2023-12-06 20:47:53,578 basehttp 28732 11976 "GET /search_results/?serverVersionInput=&managerCheckbox=on HTTP/1.1" 500 90567
